 You can now view your Streamlit app in your browser.

  URL: http://0.0.0.0:5000

2024-12-03 17:16:20.723 Examining the path of torch.classes raised: Tried to instantiate class '__path__._path', but it does not exist! Ensure that it is registered via torch::class_
2024-12-03 17:16:21.896 Examining the path of torch.classes raised: Tried to instantiate class '__path__._path', but it does not exist! Ensure that it is registered via torch::class_
ERROR:utils:Error in video processing: The size of tensor a (3136) must match the size of tensor b (1568) at non-singleton dimension 1
ERROR:utils:Error in video processing: The size of tensor a (3136) must match the size of tensor b (1568) at non-singleton dimension 1
2024-12-03 17:19:12.444 Examining the path of torch.classes raised: Tried to instantiate class '__path__._path', but it does not exist! Ensure that it is registered via torch::class_
ERROR:utils:Error in video processing: The size of tensor a (3136) must match the size of tensor b (1568) at non-singleton dimension 1
2024-12-03 17:20:08.724 Uncaught app exception
Traceback (most recent call last):
  File "/home/runner/VideoActionClassifier/.pythonlibs/lib/python3.11/site-packages/huggingface_hub/utils/_http.py", line 406, in hf_raise_for_status
    response.raise_for_status()
  File "/home/runner/VideoActionClassifier/.pythonlibs/lib/python3.11/site-packages/requests/models.py", line 1024, in raise_for_status
    raise HTTPError(http_error_msg, response=self)
requests.exceptions.HTTPError: 401 Client Error: Unauthorized for url: https://huggingface.co/MCG-NJU/videomae-base-finetuned-ucf101/resolve/main/preprocessor_config.json

The above exception was the direct cause of the following exception:

Traceback (most recent call last):
  File "/home/runner/VideoActionClassifier/.pythonlibs/lib/python3.11/site-packages/transformers/utils/hub.py", line 403, in cached_file
    resolved_file = hf_hub_download(
                    ^^^^^^^^^^^^^^^^
  File "/home/runner/VideoActionClassifier/.pythonlibs/lib/python3.11/site-packages/huggingface_hub/utils/_validators.py", line 114, in _inner_fn
    return fn(*args, **kwargs)
           ^^^^^^^^^^^^^^^^^^^
  File "/home/runner/VideoActionClassifier/.pythonlibs/lib/python3.11/site-packages/huggingface_hub/file_download.py", line 862, in hf_hub_download
    return _hf_hub_download_to_cache_dir(
           ^^^^^^^^^^^^^^^^^^^^^^^^^^^^^^
  File "/home/runner/VideoActionClassifier/.pythonlibs/lib/python3.11/site-packages/huggingface_hub/file_download.py", line 969, in _hf_hub_download_to_cache_dir
    _raise_on_head_call_error(head_call_error, force_download, local_files_only)
  File "/home/runner/VideoActionClassifier/.pythonlibs/lib/python3.11/site-packages/huggingface_hub/file_download.py", line 1484, in _raise_on_head_call_error
    raise head_call_error
  File "/home/runner/VideoActionClassifier/.pythonlibs/lib/python3.11/site-packages/huggingface_hub/file_download.py", line 1376, in _get_metadata_or_catch_error
    metadata = get_hf_file_metadata(
               ^^^^^^^^^^^^^^^^^^^^^
  File "/home/runner/VideoActionClassifier/.pythonlibs/lib/python3.11/site-packages/huggingface_hub/utils/_validators.py", line 114, in _inner_fn
    return fn(*args, **kwargs)
           ^^^^^^^^^^^^^^^^^^^
  File "/home/runner/VideoActionClassifier/.pythonlibs/lib/python3.11/site-packages/huggingface_hub/file_download.py", line 1296, in get_hf_file_metadata
    r = _request_wrapper(
        ^^^^^^^^^^^^^^^^^
  File "/home/runner/VideoActionClassifier/.pythonlibs/lib/python3.11/site-packages/huggingface_hub/file_download.py", line 277, in _request_wrapper
    response = _request_wrapper(
               ^^^^^^^^^^^^^^^^^
  File "/home/runner/VideoActionClassifier/.pythonlibs/lib/python3.11/site-packages/huggingface_hub/file_download.py", line 301, in _request_wrapper
    hf_raise_for_status(response)
  File "/home/runner/VideoActionClassifier/.pythonlibs/lib/python3.11/site-packages/huggingface_hub/utils/_http.py", line 454, in hf_raise_for_status
    raise _format(RepositoryNotFoundError, message, response) from e
huggingface_hub.errors.RepositoryNotFoundError: 401 Client Error. (Request ID: Root=1-674f3dc8-15f063571b164fe46797774f;fba7778a-37c3-45a3-9b6a-97f900bd58c6)

Repository Not Found for url: https://huggingface.co/MCG-NJU/videomae-base-finetuned-ucf101/resolve/main/preprocessor_config.json.
Please make sure you specified the correct `repo_id` and `repo_type`.
If you are trying to access a private or gated repo, make sure you are authenticated.
Invalid username or password.

The above exception was the direct cause of the following exception:

Traceback (most recent call last):
  File "/home/runner/VideoActionClassifier/.pythonlibs/lib/python3.11/site-packages/streamlit/runtime/scriptrunner/exec_code.py", line 88, in exec_func_with_error_handling
    result = func()
             ^^^^^^
  File "/home/runner/VideoActionClassifier/.pythonlibs/lib/python3.11/site-packages/streamlit/runtime/scriptrunner/script_runner.py", line 579, in code_to_exec
    exec(code, module.__dict__)
  File "/home/runner/VideoActionClassifier/main.py", line 35, in <module>
    st.session_state['processor'], st.session_state['model'] = load_model(selected_model)
                                                               ^^^^^^^^^^^^^^^^^^^^^^^^^^
  File "/home/runner/VideoActionClassifier/utils.py", line 42, in load_model
    processor = VideoMAEImageProcessor.from_pretrained(model_info["processor"])
                ^^^^^^^^^^^^^^^^^^^^^^^^^^^^^^^^^^^^^^^^^^^^^^^^^^^^^^^^^^^^^^^
  File "/home/runner/VideoActionClassifier/.pythonlibs/lib/python3.11/site-packages/transformers/image_processing_base.py", line 206, in from_pretrained
    image_processor_dict, kwargs = cls.get_image_processor_dict(pretrained_model_name_or_path, **kwargs)
                                   ^^^^^^^^^^^^^^^^^^^^^^^^^^^^^^^^^^^^^^^^^^^^^^^^^^^^^^^^^^^^^^^^^^^^^
  File "/home/runner/VideoActionClassifier/.pythonlibs/lib/python3.11/site-packages/transformers/image_processing_base.py", line 335, in get_image_processor_dict
    resolved_image_processor_file = cached_file(
                                    ^^^^^^^^^^^^
  File "/home/runner/VideoActionClassifier/.pythonlibs/lib/python3.11/site-packages/transformers/utils/hub.py", line 426, in cached_file
    raise EnvironmentError(
OSError: MCG-NJU/videomae-base-finetuned-ucf101 is not a local folder and is not a valid model identifier listed on 'https://huggingface.co/models'
If this is a private repository, make sure to pass a token having permission to this repo either by logging in with `huggingface-cli login` or by passing `token=<your_token>`
ERROR:utils:Error in video processing: The size of tensor a (3136) must match the size of tensor b (1568) at non-singleton dimension 1
ERROR:utils:Error in video processing: The size of tensor a (3136) must match the size of tensor b (1568) at non-singleton dimension 1